File: characterization/old_bend_data/bend_mod_3/mod_3_bend_trial_2.is_tens_RawData/Specimen_RawData_1.csv
Strain : Tensile strain (Extension) gauge length,"100.00000",mm
Strain : Time at removal,,s
Test : Rate 1,"100.00000",mm/min

Time,Extension,Load
(s),(mm),(N)
"0.00000","0.00000","-0.01174"
"0.10000","0.12488","-0.01003"
"0.20000","0.29826","-0.00883"
"0.30000","0.46562","-0.00300"
"0.40000","0.63244","-0.01073"
"0.50000","0.79914","-0.01228"
"0.60000","0.96589","-0.00658"
"0.70000","1.13263","-0.00744"
"0.80000","1.29917","-0.00846"
"0.90000","1.46587","-0.01164"
"1.00000","1.63249","-0.00847"
"1.10000","1.79908","-0.00770"
"1.20000","1.96577","-0.00891"
"1.30000","2.13242","-0.01375"
"1.40000","2.29917","-0.00979"
"1.50000","2.46601","-0.01466"
"1.60000","2.63262","-0.00156"
"1.70000","2.79925","0.00115"
"1.80000","2.96582","-0.00132"
"1.90000","3.13253","-0.00758"
"2.00000","3.29902","-0.00586"
"2.10000","3.46556","0.00182"
"2.20000","3.63244","-0.00588"
"2.30000","3.79913","-0.00845"
"2.40000","3.96598","-0.00572"
"2.50000","4.13263","-0.00948"
"2.60000","4.29925","-0.00634"
"2.70000","4.46587","-0.00207"
"2.80000","4.63249","-0.00568"
"2.90000","4.79910","-0.00594"
"3.00000","4.96575","-0.00575"
"3.10000","5.13246","-0.00978"
"3.20000","5.29923","-0.00509"
"3.30000","5.46605","0.00365"
"3.40000","5.63259","-0.01202"
"3.50000","5.79916","0.00570"
"3.60000","5.96574","-0.00302"
"3.70000","6.13244","-0.00578"
"3.80000","6.29907","0.00238"
"3.90000","6.46576","0.00174"
"4.00000","6.63238","-0.00939"
"4.10000","6.79926","-0.00052"
"4.20000","6.96599","-0.00235"
"4.30000","7.13247","-0.00047"
"4.40000","7.29924","-0.00350"
"4.50000","7.46585","0.00114"
"4.60000","7.63245","-0.00025"
"4.70000","7.79908","-0.00503"
"4.80000","7.96565","-0.00228"
"4.90000","8.13246","0.00011"
"5.00000","8.29926","0.00348"
"5.10000","8.46588","0.00014"
"5.20000","8.63251","-0.00464"
"5.30000","8.79911","0.00096"
"5.40000","8.96601","-0.00122"
"5.50000","9.13248","-0.00696"
"5.60000","9.29906","-0.00433"
"5.70000","9.46576","0.00333"
"5.80000","9.63235","0.00402"
"5.90000","9.79920","-0.00290"
"6.00000","9.96596","-0.00159"
"6.10000","10.13263","0.00122"
"6.20000","10.29921","0.00030"
"6.30000","10.46584","-0.00387"
"6.40000","10.63259","-0.00020"
"6.50000","10.79916","0.00462"
"6.60000","10.96561","0.00525"
"6.70000","11.13236","-0.00092"
"6.80000","11.29914","-0.00145"
"6.90000","11.46601","0.00127"
"7.00000","11.63273","0.00487"
"7.10000","11.79924","0.00457"
"7.20000","11.96588","0.00163"
"7.30000","12.13246","0.00251"
"7.40000","12.29917","0.00221"
"7.50000","12.46577","0.00856"
"7.60000","12.63241","0.00317"
"7.70000","12.79928","0.00631"
"7.80000","12.96592","0.00419"
"7.90000","13.13263","0.00790"
"8.00000","13.29931","-0.00141"
"8.10000","13.46585","0.00135"
"8.20000","13.63240","0.01040"
"8.30000","13.79903","0.00529"
"8.40000","13.96574","0.00183"
"8.50000","14.13243","0.00538"
"8.60000","14.29925","0.00486"
"8.70000","14.46597","0.00266"
"8.80000","14.63256","0.00618"
"8.90000","14.79918","0.00894"
"9.00000","14.96583","-0.00161"
"9.10000","15.13250","0.00659"
"9.20000","15.29906","0.00335"
"9.30000","15.46571","0.00640"
"9.40000","15.63239","0.00434"
"9.50000","15.79926","0.00969"
"9.60000","15.96601","0.01266"
"9.70000","16.13248","0.00565"
"9.80000","16.29911","0.01395"
"9.90000","16.46589","0.01088"
"10.00000","16.63265","0.00034"
"10.10000","16.79913","0.01332"
"10.20000","16.96576","0.00158"
"10.30000","17.13245","0.01007"
"10.40000","17.29922","0.01186"
"10.50000","17.46597","0.00997"
"10.60000","17.63262","0.00467"
"10.70000","17.79926","0.01179"
"10.80000","17.96583","0.00984"
"10.90000","18.13250","0.01352"
"11.00000","18.29912","0.01672"
"11.10000","18.46568","0.00809"
"11.20000","18.63234","0.00989"
"11.30000","18.79915","0.01554"
"11.40000","18.96597","0.01202"
"11.50000","19.13261","0.01870"
"11.60000","19.29922","0.00750"
"11.70000","19.46589","0.01537"
"11.80000","19.63251","0.00547"
"11.90000","19.79911","0.02178"
"12.00000","19.96574","0.01716"
"12.10000","20.13241","0.01394"
"12.20000","20.29921","0.01590"
"12.30000","20.46605","0.01287"
"12.40000","20.63264","0.01343"
"12.50000","20.79927","0.01665"
"12.60000","20.96587","0.02128"
"12.70000","21.13246","0.01811"
"12.80000","21.29908","0.01674"
"12.90000","21.46564","0.01822"
"13.00000","21.63247","0.00754"
"13.10000","21.79939","0.01835"
"13.20000","21.96593","0.02260"
"13.30000","22.13260","0.02609"
"13.40000","22.29925","0.02109"
"13.50000","22.46583","0.02237"
"13.60000","22.63250","0.01591"
"13.70000","22.79909","0.01221"
"13.80000","22.96568","0.00558"
"13.90000","23.13239","0.01130"
"14.00000","23.29927","0.01386"
"14.10000","23.46597","0.01626"
"14.20000","23.63260","0.01609"
"14.30000","23.79914","0.02135"
"14.40000","23.96572","0.02203"
"14.50000","24.13249","0.01931"
"14.60000","24.29913","0.02355"
"14.70000","24.46585","0.02223"
"14.80000","24.63241","0.02187"
"14.90000","24.79924","0.02652"
"15.00000","24.96601","0.01675"
"15.10000","25.13256","0.02341"
"15.20000","25.29919","0.02484"
"15.30000","25.46595","0.01780"
"15.40000","25.63247","0.02504"
"15.50000","25.79906","0.02960"
"15.60000","25.96572","0.02605"
"15.70000","26.13247","0.02512"
"15.80000","26.29918","0.02854"
"15.90000","26.46588","0.03028"
"16.00000","26.63260","0.02128"
"16.10000","26.79918","0.02656"
"16.20000","26.96593","0.02757"
"16.30000","27.13260","0.03000"
"16.40000","27.29910","0.03560"
"16.50000","27.46570","0.02493"
"16.60000","27.63251","0.02498"
"16.70000","27.79927","0.02798"
"16.80000","27.96595","0.02638"
"16.90000","28.13264","0.03425"
"17.00000","28.29927","0.03265"
"17.10000","28.46587","0.02635"
"17.20000","28.63249","0.02652"
"17.30000","28.79909","0.02789"
"17.40000","28.96563","0.02954"
"17.50000","29.13236","0.03272"
"17.60000","29.29925","0.03431"
"17.70000","29.46600","0.03721"
"17.80000","29.63259","0.04908"
"17.90000","29.79921","0.04287"
"18.00000","29.96588","0.05170"
"18.10000","30.13242","0.04573"
"18.20000","30.29906","0.05574"
"18.30000","30.46576","0.04872"
"18.40000","30.63238","0.06214"
"18.50000","30.79925","0.06512"
"18.60000","30.96594","0.06606"
"18.70000","31.13262","0.07614"
"18.80000","31.29929","0.07260"
"18.90000","31.46576","0.07187"
"19.00000","31.63236","0.07815"
"19.10000","31.79907","0.08358"
"19.20000","31.96578","0.08842"
"19.30000","32.13245","0.09731"
"19.40000","32.29924","0.09473"
"19.50000","32.46601","0.09345"
"19.60000","32.63260","0.10971"
"19.70000","32.79926","0.11073"
"19.80000","32.96582","0.11713"
"19.90000","33.13253","0.11350"
"20.00000","33.29911","0.12586"
"20.10000","33.46567","0.12944"
"20.20000","33.63248","0.12442"
"20.30000","33.79925","0.13974"
"20.40000","33.96592","0.14104"
"20.50000","34.13254","0.12815"
"20.60000","34.29915","0.15085"
"20.70000","34.46584","0.14195"
"20.80000","34.63245","0.15828"
"20.90000","34.79907","0.16754"
"21.00000","34.96571","0.17083"
"21.10000","35.13245","0.17756"
"21.20000","35.29922","0.17966"
"21.30000","35.46601","0.18934"
"21.40000","35.63257","0.18961"
"21.50000","35.79925","0.19180"
"21.60000","35.96591","0.16619"
"21.70000","36.13259","0.20046"
"21.80000","36.29913","0.20273"
"21.90000","36.46565","0.20828"
"22.00000","36.63240","0.21208"
"22.10000","36.79911","0.22776"
"22.20000","36.96601","0.22398"
"22.30000","37.13261","0.17950"
"22.40000","37.29919","0.20524"
"22.50000","37.46584","0.23484"
"22.60000","37.63252","0.26344"
"22.70000","37.79903","0.25448"
"22.80000","37.96576","0.25485"
"22.90000","38.13238","0.26285"
"23.00000","38.29920","0.25569"
"23.10000","38.46595","0.26590"
"23.20000","38.63260","0.26917"
"23.30000","38.79931","0.27695"
"23.40000","38.96580","0.28788"
"23.50000","39.13238","0.29512"
"23.60000","39.29897","0.29687"
"23.70000","39.46572","0.30545"
"23.80000","39.63247","0.31358"
"23.90000","39.79931","0.31712"
"24.00000","39.96599","0.32327"
"24.10000","40.13256","0.33372"
"24.20000","40.29922","0.33807"
"24.30000","40.46591","0.34841"
"24.40000","40.63242","0.33692"
"24.50000","40.79911","0.35378"
"24.60000","40.96574","0.35320"
"24.70000","41.13239","0.35901"
"24.80000","41.29930","0.35916"
"24.90000","41.46597","0.37970"
"25.00000","41.63248","0.38998"
"25.10000","41.79911","0.38883"
"25.20000","41.96582","0.39151"
"25.30000","42.13246","0.40360"
"25.40000","42.29906","0.39916"
"25.50000","42.46572","0.41849"
"25.60000","42.63243","0.41979"
"25.70000","42.79919","0.41268"
"25.80000","42.96600","0.42939"
"25.90000","43.13254","0.44408"
"26.00000","43.29918","0.44944"
"26.10000","43.46587","0.45247"
"26.20000","43.63246","0.46011"
"26.30000","43.79913","0.47154"
"26.40000","43.96569","0.47822"
"26.50000","44.13242","0.47142"
"26.60000","44.29920","0.48898"
"26.70000","44.46591","0.47494"
"26.80000","44.63273","0.48632"
"26.90000","44.79911","0.49689"
"27.00000","44.96583","0.50443"
"27.10000","45.13246","0.51148"
"27.20000","45.29909","0.51503"
"27.30000","45.46565","0.51911"
"27.40000","45.63242","0.53985"
"27.50000","45.79919","0.54254"
"27.60000","45.96592","0.54374"
"27.70000","46.13263","0.54267"
"27.80000","46.29923","0.54830"
"27.90000","46.46584","0.55176"
"28.00000","46.63250","0.57141"
"28.10000","46.79901","0.57594"
"28.20000","46.96555","0.57768"
"28.30000","47.13241","0.59265"
"28.40000","47.29930","0.59507"
"28.50000","47.46604","0.59336"
"28.60000","47.63247","0.60358"
"28.70000","47.79924","0.61485"
"28.80000","47.96586","0.61409"
"28.90000","48.13239","0.61643"
"29.00000","48.29903","0.61747"
"29.10000","48.46561","0.62153"
"29.20000","48.63237","0.62483"
"29.30000","48.79926","0.63772"
"29.40000","48.96599","0.64125"
"29.50000","49.13269","0.65553"
"29.60000","49.29910","0.67097"
"29.70000","49.46577","0.68340"
"29.80000","49.63253","0.68686"
"29.90000","49.79907","0.68698"
"30.00000","49.96571","0.70493"
"30.10000","50.13241","0.70353"
"30.20000","50.29922","0.70744"
"30.30000","50.46601","0.71946"
"30.40000","50.63256","0.71287"
"30.50000","50.79924","0.73181"
"30.60000","50.96583","0.73680"
"30.70000","51.13252","0.73638"
"30.80000","51.29909","0.73973"
"30.90000","51.46567","0.73825"
"31.00000","51.63246","0.74679"
"31.10000","51.79918","0.74961"
"31.20000","51.96592","0.76297"
"31.30000","52.13256","0.76540"
"31.40000","52.29930","0.77277"
"31.50000","52.46585","0.78599"
"31.60000","52.63244","0.81197"
"31.70000","52.79905","0.81708"
"31.80000","52.96577","0.81952"
"31.90000","53.13229","0.83041"
"32.00000","53.29926","0.82565"
"32.10000","53.46593","0.83943"
"32.20000","53.63255","0.84573"
"32.30000","53.79919","0.85475"
"32.40000","53.96581","0.85411"
"32.50000","54.13254","0.86068"
"32.60000","54.29904","0.86373"
"32.70000","54.46562","0.88647"
"32.80000","54.63222","0.90569"
"32.90000","54.79916","0.90021"
"33.00000","54.96619","0.90032"
"33.10000","55.13267","0.90254"
"33.20000","55.29925","0.90426"
"33.30000","55.46586","0.91816"
"33.40000","55.63246","0.93123"
"33.50000","55.79911","0.93380"
"33.60000","55.96562","0.94070"
"33.70000","56.13245","0.96154"
"33.80000","56.29929","0.97800"
"33.90000","56.46592","0.98190"
"34.00000","56.63266","0.98718"
"34.10000","56.79917","0.99443"
"34.20000","56.96577","0.99302"
"34.30000","57.13240","1.00961"
"34.40000","57.29908","1.01378"
"34.50000","57.46577","1.01346"
"34.60000","57.63238","1.01438"
"34.70000","57.79926","1.03278"
"34.80000","57.96599","1.06035"
"34.90000","58.13258","1.07871"
"35.00000","58.29927","1.07709"
"35.10000","58.46582","1.08214"
"35.20000","58.63242","1.06412"
"35.30000","58.79912","1.08236"
"35.40000","58.96572","1.09962"
"35.50000","59.13243","1.09859"
"35.60000","59.29929","1.09797"
"35.70000","59.46596","1.10160"
"35.80000","59.63255","1.11958"
"35.90000","59.79911","1.14879"
"36.00000","59.96591","1.16473"
"36.10000","60.13253","1.17750"
"36.20000","60.29906","1.18432"
"36.30000","60.46578","1.19460"
"36.40000","60.63246","1.21274"
"36.50000","60.79919","1.20718"
"36.60000","60.96598","1.20057"
"36.70000","61.13256","1.21275"
"36.80000","61.29919","1.22630"
"36.90000","61.46584","1.25802"
"37.00000","61.63254","1.26702"
"37.10000","61.79909","1.28087"
"37.20000","61.96571","1.27710"
"37.30000","62.13232","1.25284"
"37.40000","62.29914","1.26526"
"37.50000","62.46601","1.27070"
"37.60000","62.63272","1.29157"
"37.70000","62.79929","1.29481"
"37.80000","62.96581","1.32539"
"37.90000","63.13253","1.34845"
"38.00000","63.29910","1.37395"
"38.10000","63.46566","1.38225"
"38.20000","63.63239","1.38359"
"38.30000","63.79925","1.37460"
"38.40000","63.96598","1.38352"
"38.50000","64.13258","1.39692"
"38.60000","64.29919","1.40776"
"38.70000","64.46580","1.40282"
"38.80000","64.63246","1.40495"
"38.90000","64.79903","1.39171"
"39.00000","64.96571","1.42430"
"39.10000","65.13240","1.43053"
"39.20000","65.29951","1.44932"
"39.30000","65.46596","1.44278"
"39.40000","65.63261","1.44172"
"39.50000","65.79925","1.47733"
"39.60000","65.96586","1.49123"
"39.70000","66.13251","1.49060"
"39.80000","66.29904","1.49381"
"39.90000","66.46578","1.49595"
"40.00000","66.63248","1.52271"
"40.10000","66.79922","1.55122"
"40.20000","66.96597","1.55436"
"40.30000","67.13251","1.56251"
"40.40000","67.29921","1.57052"
"40.50000","67.46583","1.59285"
"40.60000","67.63248","1.62869"
"40.70000","67.79909","1.63308"
"40.80000","67.96572","1.64349"
"40.90000","68.13248","1.62087"
"41.00000","68.29928","1.62482"
"41.10000","68.46590","1.65229"
"41.20000","68.63260","1.66377"
"41.30000","68.79917","1.67804"
"41.40000","68.96581","1.67038"
"41.50000","69.13252","1.68062"
"41.60000","69.29903","1.72205"
"41.70000","69.46574","1.74717"
"41.80000","69.63245","1.74900"
"41.90000","69.79917","1.73923"
"42.00000","69.96584","1.72680"
"42.10000","70.13250","1.74846"
"42.20000","70.29930","1.76750"
"42.30000","70.46598","1.78314"
"42.40000","70.63251","1.79194"
"42.50000","70.79910","1.79946"
"42.60000","70.96564","1.84453"
"42.70000","71.13244","1.85343"
"42.80000","71.29918","1.87553"
"42.90000","71.46601","1.88744"
"43.00000","71.63261","1.87778"
"43.10000","71.79924","1.89538"
"43.20000","71.96583","1.91569"
"43.30000","72.13249","1.92327"
"43.40000","72.29903","1.93522"
"43.50000","72.46562","1.92553"
"43.60000","72.63239","1.92501"
"43.70000","72.79921","1.95639"
"43.80000","72.96600","1.99575"
"43.90000","73.13264","2.00459"
"44.00000","73.29918","2.00195"
"44.10000","73.46574","2.00223"
"44.20000","73.63245","2.03845"
"44.30000","73.79907","2.05406"
"44.40000","73.96576","2.06377"
"44.50000","74.13242","2.06329"
"44.60000","74.29924","2.08140"
"44.70000","74.46602","2.10329"
"44.80000","74.63263","2.14720"
"44.90000","74.79925","2.16835"
"45.00000","74.96583","2.17091"
"45.10000","75.13243","2.16537"
"45.20000","75.29910","2.18099"
"45.30000","75.46574","2.20817"
"45.40000","75.63249","2.21817"
"45.50000","75.79925","2.20826"
"45.60000","75.96597","2.23262"
"45.70000","76.13259","2.27539"
"45.80000","76.29921","2.31611"
"45.90000","76.46589","2.33830"
"46.00000","76.63245","2.37129"
"46.10000","76.79909","2.39093"
"46.20000","76.96571","2.40162"
"46.30000","77.13245","2.42595"
"46.40000","77.29922","2.47353"
"46.50000","77.46590","2.50864"
"46.60000","77.63243","2.53172"
"46.70000","77.79920","2.55630"
"46.80000","77.96597","2.62017"
"46.90000","78.13259","2.66912"
"47.00000","78.29904","2.70682"
"47.10000","78.46568","2.74278"
"47.20000","78.63245","2.77013"
"47.30000","78.79916","2.79125"
"47.40000","78.96598","2.80111"
"47.50000","79.13262","2.83846"
"47.60000","79.29916","2.87177"
"47.70000","79.46584","2.89514"
"47.80000","79.63251","2.93559"
"47.90000","79.79913","2.98469"
"48.00000","79.96559","3.02235"
"48.10000","80.13229","3.07505"
"48.20000","80.29926","3.13637"
"48.30000","80.46597","3.20851"
"48.40000","80.63264","3.26287"
"48.50000","80.79923","3.29948"
"48.60000","80.96584","3.31463"
"48.70000","81.13245","3.33368"
"48.80000","81.29916","3.38995"
"48.90000","81.46581","3.42295"
"49.00000","81.63234","3.46213"
"49.10000","81.79926","3.49111"
"49.20000","81.96600","3.53597"
"49.30000","82.13251","3.59114"
"49.40000","82.29922","3.65155"
"49.50000","82.46587","3.73060"
"49.60000","82.63242","3.81238"
"49.70000","82.79904","3.87356"
"49.80000","82.96571","3.92028"
"49.90000","83.13258","3.95339"
"50.00000","83.29918","3.98167"
"50.10000","83.46592","4.01690"
"50.20000","83.63250","4.06952"
"50.30000","83.79912","4.10350"
"50.40000","83.96588","4.14171"
"50.50000","84.13248","4.17667"
"50.60000","84.29899","4.24392"
"50.70000","84.46573","4.33053"
"50.80000","84.63241","4.41347"
"50.90000","84.79929","4.49148"
"51.00000","84.96597","4.56959"
"51.10000","85.13245","4.63807"
"51.20000","85.29903","4.70739"
"51.30000","85.46582","4.75446"
"51.40000","85.63261","4.78321"
"51.50000","85.79913","4.82355"
"51.60000","85.96564","4.86997"
"51.70000","86.13241","4.90767"
"51.80000","86.29922","4.94917"
"51.90000","86.46597","5.01650"
"52.00000","86.63251","5.07036"
"52.10000","86.79917","5.16756"
"52.20000","86.96587","5.24695"
"52.30000","87.13246","5.34466"
"52.40000","87.29919","5.44921"
"52.50000","87.46571","5.52760"
"52.60000","87.63231","5.62296"
"52.70000","87.79916","5.69835"
"52.80000","87.96597","5.77110"
"52.90000","88.13261","5.82070"
"53.00000","88.29913","5.84034"
"53.10000","88.46585","5.91212"
"53.20000","88.63242","5.96065"
"53.30000","88.79906","6.00868"
"53.40000","88.96577","6.08465"
"53.50000","89.13236","6.15937"
"53.60000","89.29911","6.24327"
"53.70000","89.46606","6.34004"
"53.80000","89.63262","6.42343"
"53.90000","89.79929","6.52481"
"54.00000","89.96590","6.62625"
"54.02100","90.00097","6.64405"