File: characterization/bend_mod_3/mod_3_bend_trial_3.is_tens_RawData/Specimen_RawData_1.csv
Strain : Tensile strain (Extension) gauge length,"100.00000",mm
Strain : Time at removal,,s
Test : Rate 1,"100.00000",mm/min

Time,Extension,Load
(s),(mm),(N)
"0.00000","0.00002","-0.00458"
"0.10000","0.12478","-0.01411"
"0.20000","0.29829","-0.00862"
"0.30000","0.46562","-0.00254"
"0.40000","0.63247","-0.00542"
"0.50000","0.79916","0.00255"
"0.60000","0.96588","-0.00667"
"0.70000","1.13261","-0.00576"
"0.80000","1.29923","-0.01896"
"0.90000","1.46587","-0.00978"
"1.00000","1.63245","-0.01027"
"1.10000","1.79907","-0.00775"
"1.20000","1.96577","-0.00781"
"1.30000","2.13235","-0.00852"
"1.40000","2.29917","-0.00603"
"1.50000","2.46606","-0.01050"
"1.60000","2.63259","-0.01392"
"1.70000","2.79923","-0.00771"
"1.80000","2.96591","-0.00874"
"1.90000","3.13253","-0.00878"
"2.00000","3.29897","-0.01364"
"2.10000","3.46558","-0.01232"
"2.20000","3.63242","-0.00171"
"2.30000","3.79915","-0.01411"
"2.40000","3.96600","-0.00562"
"2.50000","4.13259","-0.00707"
"2.60000","4.29923","-0.00386"
"2.70000","4.46588","-0.01709"
"2.80000","4.63248","-0.00622"
"2.90000","4.79911","-0.00638"
"3.00000","4.96575","0.00223"
"3.10000","5.13241","-0.00603"
"3.20000","5.29925","-0.00404"
"3.30000","5.46597","-0.00445"
"3.40000","5.63262","-0.00391"
"3.50000","5.79916","-0.00290"
"3.60000","5.96577","-0.01082"
"3.70000","6.13244","-0.01106"
"3.80000","6.29914","-0.00327"
"3.90000","6.46572","-0.00550"
"4.00000","6.63238","-0.00372"
"4.10000","6.79924","-0.00238"
"4.20000","6.96601","-0.00548"
"4.30000","7.13249","-0.00567"
"4.40000","7.29925","-0.00169"
"4.50000","7.46587","-0.00420"
"4.60000","7.63244","-0.01355"
"4.70000","7.79911","-0.00068"
"4.80000","7.96568","-0.00159"
"4.90000","8.13247","-0.00828"
"5.00000","8.29927","0.00011"
"5.10000","8.46591","-0.00607"
"5.20000","8.63255","-0.00570"
"5.30000","8.79914","-0.00239"
"5.40000","8.96588","0.00126"
"5.50000","9.13255","0.00615"
"5.60000","9.29902","-0.00720"
"5.70000","9.46575","-0.00082"
"5.80000","9.63234","0.00030"
"5.90000","9.79921","-0.00763"
"6.00000","9.96591","0.00010"
"6.10000","10.13273","0.00273"
"6.20000","10.29921","0.00420"
"6.30000","10.46585","-0.00430"
"6.40000","10.63265","-0.00302"
"6.50000","10.79912","0.00788"
"6.60000","10.96558","-0.00063"
"6.70000","11.13235","0.00796"
"6.80000","11.29917","0.00449"
"6.90000","11.46612","0.00800"
"7.00000","11.63261","-0.00602"
"7.10000","11.79930","0.00032"
"7.20000","11.96590","-0.00783"
"7.30000","12.13244","0.00065"
"7.40000","12.29919","-0.00063"
"7.50000","12.46570","0.00301"
"7.60000","12.63241","0.00469"
"7.70000","12.79927","-0.00012"
"7.80000","12.96593","0.00332"
"7.90000","13.13266","0.00104"
"8.00000","13.29927","0.00863"
"8.10000","13.46584","0.00055"
"8.20000","13.63245","0.00377"
"8.30000","13.79900","0.00211"
"8.40000","13.96573","0.00361"
"8.50000","14.13244","0.00281"
"8.60000","14.29923","0.00830"
"8.70000","14.46595","0.01111"
"8.80000","14.63259","0.01040"
"8.90000","14.79922","0.00603"
"9.00000","14.96585","-0.00129"
"9.10000","15.13244","0.01009"
"9.20000","15.29904","0.00143"
"9.30000","15.46572","0.00428"
"9.40000","15.63242","0.00234"
"9.50000","15.79924","0.00899"
"9.60000","15.96600","0.00250"
"9.70000","16.13251","0.00247"
"9.80000","16.29907","0.00670"
"9.90000","16.46585","0.00824"
"10.00000","16.63270","0.01141"
"10.10000","16.79914","0.00798"
"10.20000","16.96571","0.01553"
"10.30000","17.13241","0.01021"
"10.40000","17.29922","0.00529"
"10.50000","17.46601","0.01370"
"10.60000","17.63254","0.00506"
"10.70000","17.79924","0.01066"
"10.80000","17.96589","0.01157"
"10.90000","18.13249","0.00790"
"11.00000","18.29914","0.01083"
"11.10000","18.46577","0.01026"
"11.20000","18.63230","0.01455"
"11.30000","18.79918","0.01341"
"11.40000","18.96595","0.01230"
"11.50000","19.13264","0.01750"
"11.60000","19.29926","0.01000"
"11.70000","19.46594","0.01377"
"11.80000","19.63248","0.01433"
"11.90000","19.79914","0.00879"
"12.00000","19.96579","0.01349"
"12.10000","20.13243","0.01512"
"12.20000","20.29916","0.01361"
"12.30000","20.46598","0.01637"
"12.40000","20.63265","0.01957"
"12.50000","20.79928","0.01156"
"12.60000","20.96585","0.01494"
"12.70000","21.13249","0.01926"
"12.80000","21.29906","0.01256"
"12.90000","21.46566","0.01240"
"13.00000","21.63252","0.01499"
"13.10000","21.79933","0.02063"
"13.20000","21.96594","0.01897"
"13.30000","22.13258","0.02353"
"13.40000","22.29924","0.01707"
"13.50000","22.46586","0.02243"
"13.60000","22.63251","0.01419"
"13.70000","22.79910","0.01937"
"13.80000","22.96570","0.01560"
"13.90000","23.13247","0.02517"
"14.00000","23.29922","0.02230"
"14.10000","23.46599","0.02455"
"14.20000","23.63260","0.02624"
"14.30000","23.79916","0.02008"
"14.40000","23.96570","0.01910"
"14.50000","24.13247","0.02065"
"14.60000","24.29925","0.01942"
"14.70000","24.46579","0.02630"
"14.80000","24.63247","0.02250"
"14.90000","24.79925","0.02344"
"15.00000","24.96600","0.02291"
"15.10000","25.13257","0.01973"
"15.20000","25.29917","0.01885"
"15.30000","25.46590","0.02440"
"15.40000","25.63253","0.01948"
"15.50000","25.79905","0.03049"
"15.60000","25.96572","0.02358"
"15.70000","26.13246","0.02189"
"15.80000","26.29917","0.02924"
"15.90000","26.46591","0.02025"
"16.00000","26.63259","0.02763"
"16.10000","26.79917","0.01726"
"16.20000","26.96588","0.01221"
"16.30000","27.13250","0.02908"
"16.40000","27.29906","0.03666"
"16.50000","27.46576","0.03033"
"16.60000","27.63252","0.02275"
"16.70000","27.79925","0.02509"
"16.80000","27.96600","0.02505"
"16.90000","28.13264","0.02758"
"17.00000","28.29922","0.03078"
"17.10000","28.46593","0.02935"
"17.20000","28.63248","0.02592"
"17.30000","28.79909","0.02590"
"17.40000","28.96560","0.03127"
"17.50000","29.13233","0.03142"
"17.60000","29.29939","0.04385"
"17.70000","29.46597","0.03384"
"17.80000","29.63262","0.03445"
"17.90000","29.79922","0.04320"
"18.00000","29.96587","0.04456"
"18.10000","30.13241","0.04957"
"18.20000","30.29906","0.05374"
"18.30000","30.46577","0.05269"
"18.40000","30.63234","0.05676"
"18.50000","30.79924","0.05834"
"18.60000","30.96591","0.06696"
"18.70000","31.13262","0.06456"
"18.80000","31.29930","0.07451"
"18.90000","31.46576","0.07746"
"19.00000","31.63237","0.06981"
"19.10000","31.79909","0.07360"
"19.20000","31.96587","0.07710"
"19.30000","32.13249","0.08681"
"19.40000","32.29922","0.08705"
"19.50000","32.46602","0.09196"
"19.60000","32.63256","0.09654"
"19.70000","32.79922","0.10068"
"19.80000","32.96586","0.10879"
"19.90000","33.13254","0.11192"
"20.00000","33.29908","0.12144"
"20.10000","33.46571","0.12311"
"20.20000","33.63243","0.12757"
"20.30000","33.79925","0.13142"
"20.40000","33.96594","0.13615"
"20.50000","34.13251","0.13964"
"20.60000","34.29915","0.13570"
"20.70000","34.46586","0.15141"
"20.80000","34.63253","0.15188"
"20.90000","34.79907","0.16979"
"21.00000","34.96577","0.17476"
"21.10000","35.13239","0.14692"
"21.20000","35.29919","0.18017"
"21.30000","35.46601","0.18697"
"21.40000","35.63263","0.18840"
"21.50000","35.79922","0.19301"
"21.60000","35.96584","0.19328"
"21.70000","36.13256","0.20249"
"21.80000","36.29908","0.19929"
"21.90000","36.46571","0.18425"
"22.00000","36.63243","0.20945"
"22.10000","36.79911","0.23310"
"22.20000","36.96613","0.20904"
"22.30000","37.13258","0.22349"
"22.40000","37.29924","0.22846"
"22.50000","37.46584","0.24222"
"22.60000","37.63248","0.23728"
"22.70000","37.79897","0.24626"
"22.80000","37.96573","0.26243"
"22.90000","38.13240","0.25611"
"23.00000","38.29914","0.27540"
"23.10000","38.46599","0.26957"
"23.20000","38.63255","0.28174"
"23.30000","38.79927","0.27468"
"23.40000","38.96580","0.29161"
"23.50000","39.13240","0.23435"
"23.60000","39.29899","0.28146"
"23.70000","39.46568","0.31418"
"23.80000","39.63252","0.31397"
"23.90000","39.79929","0.30590"
"24.00000","39.96595","0.31444"
"24.10000","40.13257","0.32823"
"24.20000","40.29926","0.32560"
"24.30000","40.46589","0.33347"
"24.40000","40.63244","0.33344"
"24.50000","40.79914","0.34508"
"24.60000","40.96576","0.33994"
"24.70000","41.13237","0.35181"
"24.80000","41.29928","0.34645"
"24.90000","41.46599","0.36325"
"25.00000","41.63251","0.37314"
"25.10000","41.79912","0.37416"
"25.20000","41.96579","0.38247"
"25.30000","42.13249","0.38577"
"25.40000","42.29905","0.39936"
"25.50000","42.46576","0.40285"
"25.60000","42.63237","0.40599"
"25.70000","42.79923","0.41131"
"25.80000","42.96603","0.41136"
"25.90000","43.13251","0.41491"
"26.00000","43.29918","0.42446"
"26.10000","43.46588","0.43892"
"26.20000","43.63247","0.43734"
"26.30000","43.79912","0.45233"
"26.40000","43.96577","0.46360"
"26.50000","44.13243","0.45511"
"26.60000","44.29908","0.45922"
"26.70000","44.46590","0.47983"
"26.80000","44.63251","0.46947"
"26.90000","44.79945","0.47632"
"27.00000","44.96585","0.48504"
"27.10000","45.13244","0.49475"
"27.20000","45.29904","0.50580"
"27.30000","45.46567","0.49794"
"27.40000","45.63242","0.50759"
"27.50000","45.79918","0.52443"
"27.60000","45.96588","0.52493"
"27.70000","46.13262","0.53690"
"27.80000","46.29926","0.53904"
"27.90000","46.46584","0.53880"
"28.00000","46.63249","0.53850"
"28.10000","46.79900","0.56077"
"28.20000","46.96554","0.57298"
"28.30000","47.13241","0.57380"
"28.40000","47.29926","0.57863"
"28.50000","47.46600","0.58163"
"28.60000","47.63247","0.58363"
"28.70000","47.79924","0.60628"
"28.80000","47.96587","0.60485"
"28.90000","48.13244","0.60505"
"29.00000","48.29904","0.60850"
"29.10000","48.46562","0.61183"
"29.20000","48.63238","0.61217"
"29.30000","48.79922","0.63373"
"29.40000","48.96595","0.62262"
"29.50000","49.13265","0.63419"
"29.60000","49.29914","0.64394"
"29.70000","49.46580","0.66183"
"29.80000","49.63245","0.67070"
"29.90000","49.79906","0.67850"
"30.00000","49.96574","0.68389"
"30.10000","50.13240","0.67607"
"30.20000","50.29922","0.69869"
"30.30000","50.46600","0.69570"
"30.40000","50.63261","0.69833"
"30.50000","50.79920","0.70107"
"30.60000","50.96582","0.70638"
"30.70000","51.13250","0.72269"
"30.80000","51.29909","0.73625"
"30.90000","51.46576","0.73024"
"31.00000","51.63245","0.72895"
"31.10000","51.79916","0.73782"
"31.20000","51.96593","0.74078"
"31.30000","52.13256","0.74951"
"31.40000","52.29931","0.75587"
"31.50000","52.46589","0.76313"
"31.60000","52.63243","0.77748"
"31.70000","52.79905","0.78748"
"31.80000","52.96569","0.80991"
"31.90000","53.13239","0.81215"
"32.00000","53.29924","0.81883"
"32.10000","53.46591","0.82042"
"32.20000","53.63252","0.82531"
"32.30000","53.79917","0.83284"
"32.40000","53.96582","0.84593"
"32.50000","54.13234","0.85035"
"32.60000","54.29912","0.86259"
"32.70000","54.46563","0.86580"
"32.80000","54.63218","0.87347"
"32.90000","54.79926","0.88424"
"33.00000","54.96621","0.88934"
"33.10000","55.13260","0.88580"
"33.20000","55.29922","0.88566"
"33.30000","55.46589","0.89417"
"33.40000","55.63243","0.90624"
"33.50000","55.79911","0.91198"
"33.60000","55.96560","0.92364"
"33.70000","56.13245","0.92713"
"33.80000","56.29924","0.94516"
"33.90000","56.46595","0.95341"
"34.00000","56.63262","0.96721"
"34.10000","56.79926","0.96958"
"34.20000","56.96575","0.96787"
"34.30000","57.13242","0.97431"
"34.40000","57.29904","0.99171"
"34.50000","57.46576","1.00527"
"34.60000","57.63242","1.00187"
"34.70000","57.79927","1.00022"
"34.80000","57.96599","1.02440"
"34.90000","58.13258","1.05076"
"35.00000","58.29925","1.05983"
"35.10000","58.46586","1.05788"
"35.20000","58.63244","1.05597"
"35.30000","58.79908","1.05195"
"35.40000","58.96571","1.06487"
"35.50000","59.13243","1.06944"
"35.60000","59.29907","1.08313"
"35.70000","59.46613","1.07557"
"35.80000","59.63258","1.09073"
"35.90000","59.79904","1.11859"
"36.00000","59.96594","1.14233"
"36.10000","60.13253","1.14926"
"36.20000","60.29909","1.15832"
"36.30000","60.46571","1.16278"
"36.40000","60.63245","1.18375"
"36.50000","60.79923","1.18024"
"36.60000","60.96595","1.18108"
"36.70000","61.13259","1.19013"
"36.80000","61.29914","1.19271"
"36.90000","61.46582","1.21710"
"37.00000","61.63253","1.23264"
"37.10000","61.79909","1.24423"
"37.20000","61.96569","1.25991"
"37.30000","62.13231","1.24522"
"37.40000","62.29909","1.22716"
"37.50000","62.46612","1.24060"
"37.60000","62.63264","1.26005"
"37.70000","62.79930","1.27852"
"37.80000","62.96582","1.28358"
"37.90000","63.13250","1.32146"
"38.00000","63.29911","1.34415"
"38.10000","63.46567","1.35252"
"38.20000","63.63235","1.36208"
"38.30000","63.79924","1.36652"
"38.40000","63.96598","1.36248"
"38.50000","64.13256","1.37967"
"38.60000","64.29922","1.40246"
"38.70000","64.46584","1.40166"
"38.80000","64.63237","1.41148"
"38.90000","64.79903","1.39487"
"39.00000","64.96574","1.40059"
"39.10000","65.13238","1.41597"
"39.20000","65.29949","1.43931"
"39.30000","65.46599","1.43605"
"39.40000","65.63261","1.42150"
"39.50000","65.79920","1.43243"
"39.60000","65.96589","1.45792"
"39.70000","66.13253","1.47301"
"39.80000","66.29900","1.47889"
"39.90000","66.46577","1.48536"
"40.00000","66.63250","1.49074"
"40.10000","66.79916","1.51155"
"40.20000","66.96602","1.53640"
"40.30000","67.13258","1.54064"
"40.40000","67.29919","1.54221"
"40.50000","67.46583","1.55612"
"40.60000","67.63248","1.59115"
"40.70000","67.79913","1.61045"
"40.80000","67.96572","1.62682"
"40.90000","68.13249","1.61010"
"41.00000","68.29922","1.60635"
"41.10000","68.46594","1.61697"
"41.20000","68.63260","1.64490"
"41.30000","68.79914","1.64350"
"41.40000","68.96581","1.65830"
"41.50000","69.13249","1.64323"
"41.60000","69.29902","1.68386"
"41.70000","69.46573","1.69985"
"41.80000","69.63255","1.71916"
"41.90000","69.79915","1.72661"
"42.00000","69.96584","1.70514"
"42.10000","70.13256","1.72817"
"42.20000","70.29936","1.74743"
"42.30000","70.46591","1.76930"
"42.40000","70.63247","1.76507"
"42.50000","70.79916","1.76169"
"42.60000","70.96566","1.80732"
"42.70000","71.13247","1.83102"
"42.80000","71.29917","1.84565"
"42.90000","71.46606","1.85917"
"43.00000","71.63258","1.85944"
"43.10000","71.79923","1.85523"
"43.20000","71.96584","1.87323"
"43.30000","72.13248","1.89296"
"43.40000","72.29906","1.90002"
"43.50000","72.46563","1.90643"
"43.60000","72.63242","1.89555"
"43.70000","72.79919","1.92184"
"43.80000","72.96593","1.95813"
"43.90000","73.13263","1.97485"
"44.00000","73.29928","1.98258"
"44.10000","73.46572","1.98167"
"44.20000","73.63240","1.99626"
"44.30000","73.79907","2.02862"
"44.40000","73.96575","2.04111"
"44.50000","74.13242","2.05613"
"44.60000","74.29923","2.05383"
"44.70000","74.46607","2.07543"
"44.80000","74.63256","2.11417"
"44.90000","74.79926","2.13149"
"45.00000","74.96586","2.14093"
"45.10000","75.13245","2.14689"
"45.20000","75.29919","2.15166"
"45.30000","75.46574","2.18514"
"45.40000","75.63246","2.19597"
"45.50000","75.79916","2.19802"
"45.60000","75.96595","2.20896"
"45.70000","76.13255","2.24433"
"45.80000","76.29921","2.28504"
"45.90000","76.46585","2.31706"
"46.00000","76.63244","2.35622"
"46.10000","76.79909","2.36346"
"46.20000","76.96571","2.37058"
"46.30000","77.13248","2.38813"
"46.40000","77.29923","2.43001"
"46.50000","77.46587","2.47085"
"46.60000","77.63245","2.48835"
"46.70000","77.79918","2.53097"
"46.80000","77.96594","2.57359"
"46.90000","78.13255","2.60883"
"47.00000","78.29903","2.65154"
"47.10000","78.46568","2.70893"
"47.20000","78.63246","2.74192"
"47.30000","78.79919","2.76380"
"47.40000","78.96595","2.77254"
"47.50000","79.13262","2.78835"
"47.60000","79.29922","2.82730"
"47.70000","79.46587","2.85441"
"47.80000","79.63250","2.89092"
"47.90000","79.79914","2.93115"
"48.00000","79.96558","2.97636"
"48.10000","80.13235","3.02781"
"48.20000","80.29917","3.08001"
"48.30000","80.46601","3.14903"
"48.40000","80.63261","3.22273"
"48.50000","80.79926","3.25315"
"48.60000","80.96586","3.28135"
"48.70000","81.13246","3.29322"
"48.80000","81.29914","3.33841"
"48.90000","81.46577","3.37319"
"49.00000","81.63232","3.39883"
"49.10000","81.79926","3.44116"
"49.20000","81.96599","3.47769"
"49.30000","82.13256","3.53379"
"49.40000","82.29926","3.59494"
"49.50000","82.46582","3.66485"
"49.60000","82.63242","3.75035"
"49.70000","82.79908","3.81745"
"49.80000","82.96572","3.87230"
"49.90000","83.13257","3.91719"
"50.00000","83.29918","3.93039"
"50.10000","83.46597","3.95907"
"50.20000","83.63246","4.00801"
"50.30000","83.79912","4.06121"
"50.40000","83.96585","4.09691"
"50.50000","84.13244","4.13668"
"50.60000","84.29903","4.19480"
"50.70000","84.46564","4.26335"
"50.80000","84.63243","4.35594"
"50.90000","84.79932","4.43400"
"51.00000","84.96599","4.51766"
"51.10000","85.13255","4.58472"
"51.20000","85.29909","4.65098"
"51.30000","85.46583","4.69584"
"51.40000","85.63268","4.73495"
"51.50000","85.79909","4.76167"
"51.60000","85.96565","4.81522"
"51.70000","86.13245","4.86173"
"51.80000","86.29922","4.90114"
"51.90000","86.46593","4.95582"
"52.00000","86.63253","5.01741"
"52.10000","86.79925","5.11513"
"52.20000","86.96585","5.19441"
"52.30000","87.13246","5.28952"
"52.40000","87.29914","5.39468"
"52.50000","87.46561","5.47914"
"52.60000","87.63234","5.57435"
"52.70000","87.79923","5.65248"
"52.80000","87.96591","5.70794"
"52.90000","88.13261","5.76067"
"53.00000","88.29911","5.80337"
"53.10000","88.46590","5.85060"
"53.20000","88.63241","5.91148"
"53.30000","88.79910","5.97054"
"53.40000","88.96572","6.04353"
"53.50000","89.13231","6.12658"
"53.60000","89.29922","6.21614"
"53.70000","89.46600","6.30337"
"53.80000","89.63256","6.39731"
"53.90000","89.79929","6.48951"
"54.00000","89.96584","6.60140"
"54.02100","90.00095","6.62304"