File: characterization/bend_test_sept_26/mod_4_bend_test/mod_4_bend_test_trial_1.is_tens_RawData/Specimen_RawData_1.csv
Strain : Tensile strain (Extension) gauge length,"100.00000",mm
Strain : Time at removal,,s
Test : Rate 1,"300.00000",mm/min

Time,Extension,Load
(s),(mm),(N)
"0.00000","0.00002","-0.01490"
"0.10000","0.37748","-0.01031"
"0.20000","0.89506","-0.01100"
"0.30000","1.39708","-0.00100"
"0.40000","1.89752","-0.00721"
"0.50000","2.39746","-0.00444"
"0.60000","2.89764","0.00419"
"0.70000","3.39755","0.00560"
"0.80000","3.89745","0.00980"
"0.90000","4.39755","0.00579"
"1.00000","4.89748","0.00742"
"1.10000","5.39745","0.01000"
"1.20000","5.89748","0.00904"
"1.30000","6.39754","0.02187"
"1.40000","6.89749","0.02179"
"1.50000","7.39747","0.02762"
"1.60000","7.89742","0.03732"
"1.70000","8.39756","0.02883"
"1.80000","8.89748","0.03895"
"1.90000","9.39755","0.05070"
"2.00000","9.89755","0.04606"
"2.10000","10.39738","0.05230"
"2.20000","10.89759","0.05289"
"2.30000","11.39744","0.05502"
"2.40000","11.89743","0.06241"
"2.50000","12.39760","0.06700"
"2.60000","12.89744","0.07350"
"2.70000","13.39763","0.07366"
"2.80000","13.89758","0.07901"
"2.90000","14.39748","0.08700"
"3.00000","14.89748","0.08768"
"3.10000","15.39737","0.10040"
"3.20000","15.89750","0.09745"
"3.30000","16.39745","0.10482"
"3.40000","16.89754","0.11890"
"3.50000","17.39759","0.12965"
"3.60000","17.89724","0.13617"
"3.70000","18.39770","0.14101"
"3.80000","18.89746","0.12347"
"3.90000","19.39739","0.14160"
"4.00000","19.89758","0.15851"
"4.10000","20.39729","0.15657"
"4.20000","20.89757","0.14839"
"4.30000","21.39753","0.16557"
"4.40000","21.89741","0.17826"
"4.50000","22.39753","0.17875"
"4.60000","22.89760","0.20680"
"4.70000","23.39766","0.20982"
"4.80000","23.89747","0.19151"
"4.90000","24.39743","0.22381"
"5.00000","24.89744","0.24436"
"5.10000","25.39732","0.22145"
"5.20000","25.89766","0.24266"
"5.30000","26.39751","0.25007"
"5.40000","26.89740","0.26351"
"5.50000","27.39761","0.27598"
"5.60000","27.89740","0.28632"
"5.70000","28.39742","0.30060"
"5.80000","28.89760","0.30324"
"5.90000","29.39745","0.31297"
"6.00000","29.89750","0.31356"
"6.10000","30.39755","0.34384"
"6.20000","30.89734","0.36958"
"6.30000","31.39746","0.39166"
"6.40000","31.89749","0.37313"
"6.50000","32.39756","0.36562"
"6.60000","32.89750","0.40474"
"6.70000","33.39764","0.42814"
"6.80000","33.89756","0.45964"
"6.90000","34.39744","0.44687"
"7.00000","34.89755","0.43436"
"7.10000","35.39747","0.46806"
"7.20000","35.89736","0.46539"
"7.30000","36.39769","0.49986"
"7.40000","36.89743","0.53696"
"7.50000","37.39753","0.52475"
"7.60000","37.89758","0.53128"
"7.70000","38.39737","0.56300"
"7.80000","38.89759","0.60968"
"7.90000","39.39750","0.58330"
"8.00000","39.89740","0.60298"
"8.10000","40.39749","0.62221"
"8.20000","40.89736","0.64802"
"8.30000","41.39767","0.65785"
"8.40000","41.89744","0.66985"
"8.50000","42.39759","0.70722"
"8.60000","42.89756","0.70962"
"8.70000","43.39733","0.71733"
"8.80000","43.89764","0.74687"
"8.90000","44.39744","0.76950"
"9.00000","44.89737","0.79647"
"9.10000","45.39753","0.81357"
"9.20000","45.89746","0.78864"
"9.30000","46.39753","0.84007"
"9.40000","46.89753","0.86791"
"9.50000","47.39747","0.88700"
"9.60000","47.89750","0.85173"
"9.70000","48.39751","0.89692"
"9.80000","48.89769","0.93725"
"9.90000","49.39749","0.97339"
"10.00000","49.89748","0.96716"
"10.10000","50.39751","0.98237"
"10.20000","50.89738","1.00136"
"10.30000","51.39748","1.01610"
"10.40000","51.89752","1.06903"
"10.50000","52.39750","1.08780"
"10.60000","52.89764","1.06770"
"10.70000","53.39751","1.08465"
"10.80000","53.89737","1.15235"
"10.90000","54.39757","1.18827"
"11.00000","54.89747","1.16206"
"11.10000","55.39745","1.12978"
"11.20000","55.89758","1.23220"
"11.30000","56.39748","1.30028"
"11.40000","56.89758","1.26347"
"11.50000","57.39750","1.28313"
"11.60000","57.89746","1.27445"
"11.70000","58.39748","1.39035"
"11.80000","58.89751","1.40369"
"11.90000","59.39762","1.33811"
"12.00000","59.89743","1.39284"
"12.10000","60.39751","1.51135"
"12.20000","60.89747","1.55665"
"12.30000","61.39730","1.44772"
"12.40000","61.89768","1.41191"
"12.50000","62.39748","1.55798"
"12.60000","62.89740","1.66835"
"12.70000","63.39762","1.76942"
"12.80000","63.89730","1.47948"
"12.90000","64.39764","1.64197"
"13.00000","64.89751","1.74346"
"13.10000","65.39742","1.79461"
"13.20000","65.89751","1.56171"
"13.30000","66.39742","1.71971"
"13.40000","66.89771","1.85640"
"13.50000","67.39745","1.77521"
"13.60000","67.89750","1.66942"
"13.70000","68.39759","1.77858"
"13.80000","68.89748","1.96868"
"13.90000","69.39767","1.87647"
"14.00000","69.89747","1.79744"
"14.10000","70.39732","1.95141"
"14.20000","70.89754","2.00242"
"14.30000","71.39737","1.84065"
"14.40000","71.89767","1.91467"
"14.50000","72.39756","2.08388"
"14.60000","72.89740","1.99940"
"14.70000","73.39751","1.90041"
"14.80000","73.89752","2.06929"
"14.90000","74.39751","2.18040"
"15.00000","74.89750","2.08020"
"15.10000","75.39746","2.07896"
"15.20000","75.89749","2.19590"
"15.30000","76.39747","2.27607"
"15.40000","76.89746","2.16112"
"15.50000","77.39752","2.26854"
"15.60000","77.89744","2.38454"
"15.70000","78.39757","2.46946"
"15.80000","78.89748","2.59076"
"15.90000","79.39747","2.69535"
"16.00000","79.89760","2.82121"
"16.10000","80.39742","2.98681"
"16.20000","80.89742","3.15828"
"16.30000","81.39753","3.34284"
"16.40000","81.89741","3.48454"
"16.50000","82.39762","3.57022"
"16.60000","82.89752","3.66812"
"16.70000","83.39751","3.77147"
"16.80000","83.89757","3.98629"
"16.90000","84.39748","4.22514"
"17.00000","84.89761","4.51599"
"17.10000","85.39742","4.75618"
"17.20000","85.89748","4.95181"
"17.30000","86.39750","4.96105"
"17.40000","86.89726","5.09431"
"17.50000","87.39769","5.40788"
"17.60000","87.89734","5.79194"
"17.70000","88.39748","6.14396"
"17.80000","88.89771","6.39751"
"17.90000","89.39742","6.43959"
"18.00000","89.89763","6.67819"
"18.02100","90.00259","6.75752"