File: characterization/old_bend_data/bend_mod_2/mod_2_bend_trial_2.is_tens_RawData/Mod2_Trial2_RawData_1.csv
Strain : Tensile strain (Extension) gauge length,"100.00000",mm
Strain : Time at removal,,s
Test : Rate 1,"100.00000",mm/min

Time,Extension,Load
(s),(mm),(N)
"0.00000","0.00002","0.00105"
"0.10000","0.12517","-0.00659"
"0.20000","0.29833","0.00763"
"0.30000","0.46570","-0.00272"
"0.40000","0.63240","0.00656"
"0.50000","0.79909","-0.00095"
"0.60000","0.96575","0.00644"
"0.70000","1.13248","-0.00081"
"0.80000","1.29918","-0.00002"
"0.90000","1.46588","0.00234"
"1.00000","1.63258","-0.00034"
"1.10000","1.79917","0.00435"
"1.20000","1.96580","-0.00275"
"1.30000","2.13242","-0.00235"
"1.40000","2.29910","0.00296"
"1.50000","2.46578","0.00438"
"1.60000","2.63253","0.00387"
"1.70000","2.79918","0.00900"
"1.80000","2.96593","0.00504"
"1.90000","3.13259","0.00123"
"2.00000","3.29920","-0.00076"
"2.10000","3.46577","0.00753"
"2.20000","3.63255","0.00718"
"2.30000","3.79906","0.00660"
"2.40000","3.96568","0.00864"
"2.50000","4.13234","0.00476"
"2.60000","4.29927","0.00926"
"2.70000","4.46598","0.00986"
"2.80000","4.63280","0.00681"
"2.90000","4.79916","0.01088"
"3.00000","4.96579","0.01397"
"3.10000","5.13242","0.00846"
"3.20000","5.29908","0.01270"
"3.30000","5.46570","0.01044"
"3.40000","5.63249","0.01900"
"3.50000","5.79927","0.00998"
"3.60000","5.96598","0.00687"
"3.70000","6.13260","0.01003"
"3.80000","6.29916","0.00327"
"3.90000","6.46570","0.00714"
"4.00000","6.63240","0.00857"
"4.10000","6.79912","0.00007"
"4.20000","6.96582","0.01727"
"4.30000","7.13253","0.01064"
"4.40000","7.29924","0.01560"
"4.50000","7.46602","0.01842"
"4.60000","7.63260","0.01206"
"4.70000","7.79914","0.01515"
"4.80000","7.96580","0.01857"
"4.90000","8.13244","0.00125"
"5.00000","8.29908","0.00820"
"5.10000","8.46578","0.01512"
"5.20000","8.63245","0.01039"
"5.30000","8.79927","0.01568"
"5.40000","8.96597","0.01013"
"5.50000","9.13253","0.00517"
"5.60000","9.29912","0.01943"
"5.70000","9.46584","0.01865"
"5.80000","9.63257","0.01731"
"5.90000","9.79911","0.02503"
"6.00000","9.96574","0.02873"
"6.10000","10.13247","0.02969"
"6.20000","10.29927","0.03071"
"6.30000","10.46596","0.02925"
"6.40000","10.63251","0.02786"
"6.50000","10.79919","0.03639"
"6.60000","10.96574","0.03518"
"6.70000","11.13248","0.03318"
"6.80000","11.29916","0.03048"
"6.90000","11.46576","0.04496"
"7.00000","11.63238","0.04152"
"7.10000","11.79913","0.04377"
"7.20000","11.96596","0.04525"
"7.30000","12.13271","0.05123"
"7.40000","12.29919","0.04653"
"7.50000","12.46580","0.05532"
"7.60000","12.63240","0.05412"
"7.70000","12.79904","0.06561"
"7.80000","12.96576","0.06700"
"7.90000","13.13244","0.06692"
"8.00000","13.29925","0.06718"
"8.10000","13.46598","0.07652"
"8.20000","13.63262","0.07748"
"8.30000","13.79921","0.07610"
"8.40000","13.96575","0.08459"
"8.50000","14.13242","0.08528"
"8.60000","14.29900","0.08187"
"8.70000","14.46572","0.09708"
"8.80000","14.63257","0.09836"
"8.90000","14.79938","0.09697"
"9.00000","14.96597","0.09707"
"9.10000","15.13259","0.10951"
"9.20000","15.29917","0.10318"
"9.30000","15.46580","0.10770"
"9.40000","15.63241","0.11339"
"9.50000","15.79908","0.11306"
"9.60000","15.96575","0.12997"
"9.70000","16.13245","0.13716"
"9.80000","16.29923","0.13136"
"9.90000","16.46594","0.14667"
"10.00000","16.63250","0.14186"
"10.10000","16.79911","0.14374"
"10.20000","16.96575","0.15511"
"10.30000","17.13254","0.15887"
"10.40000","17.29917","0.16302"
"10.50000","17.46581","0.16627"
"10.60000","17.63250","0.18025"
"10.70000","17.79927","0.17131"
"10.80000","17.96601","0.18333"
"10.90000","18.13256","0.17694"
"11.00000","18.29913","0.19118"
"11.10000","18.46579","0.20352"
"11.20000","18.63239","0.20152"
"11.30000","18.79908","0.20830"
"11.40000","18.96581","0.22265"
"11.50000","19.13245","0.22005"
"11.60000","19.29916","0.23159"
"11.70000","19.46589","0.23687"
"11.80000","19.63258","0.23983"
"11.90000","19.79937","0.23659"
"12.00000","19.96583","0.25433"
"12.10000","20.13245","0.25356"
"12.20000","20.29908","0.25469"
"12.30000","20.46574","0.26086"
"12.40000","20.63246","0.26510"
"12.50000","20.79927","0.27184"
"12.60000","20.96595","0.28787"
"12.70000","21.13262","0.28990"
"12.80000","21.29916","0.29631"
"12.90000","21.46581","0.29706"
"13.00000","21.63244","0.31186"
"13.10000","21.79903","0.31290"
"13.20000","21.96570","0.31810"
"13.30000","22.13240","0.31917"
"13.40000","22.29934","0.32723"
"13.50000","22.46598","0.33578"
"13.60000","22.63254","0.33830"
"13.70000","22.79921","0.34939"
"13.80000","22.96576","0.36180"
"13.90000","23.13242","0.37799"
"14.00000","23.29910","0.37589"
"14.10000","23.46570","0.38472"
"14.20000","23.63250","0.38793"
"14.30000","23.79921","0.40460"
"14.40000","23.96593","0.39715"
"14.50000","24.13257","0.40703"
"14.60000","24.29917","0.40771"
"14.70000","24.46575","0.41475"
"14.80000","24.63234","0.42682"
"14.90000","24.79917","0.42530"
"15.00000","24.96583","0.42862"
"15.10000","25.13246","0.44779"
"15.20000","25.29926","0.46434"
"15.30000","25.46599","0.46954"
"15.40000","25.63258","0.47710"
"15.50000","25.79914","0.48019"
"15.60000","25.96575","0.49132"
"15.70000","26.13246","0.50915"
"15.80000","26.29905","0.51098"
"15.90000","26.46572","0.51910"
"16.00000","26.63258","0.51858"
"16.10000","26.79921","0.52460"
"16.20000","26.96598","0.54374"
"16.30000","27.13244","0.56655"
"16.40000","27.29910","0.57472"
"16.50000","27.46586","0.58532"
"16.60000","27.63252","0.57178"
"16.70000","27.79909","0.57567"
"16.80000","27.96572","0.58732"
"16.90000","28.13242","0.57726"
"17.00000","28.29922","0.57896"
"17.10000","28.46594","0.58878"
"17.20000","28.63257","0.58728"
"17.30000","28.79916","0.60101"
"17.40000","28.96579","0.60612"
"17.50000","29.13249","0.62578"
"17.60000","29.29905","0.62320"
"17.70000","29.46572","0.63186"
"17.80000","29.63233","0.64788"
"17.90000","29.79919","0.66630"
"18.00000","29.96610","0.66209"
"18.10000","30.13259","0.66865"
"18.20000","30.29916","0.66956"
"18.30000","30.46576","0.67639"
"18.40000","30.63245","0.69767"
"18.50000","30.79909","0.71071"
"18.60000","30.96571","0.70917"
"18.70000","31.13248","0.71033"
"18.80000","31.29921","0.71657"
"18.90000","31.46598","0.73245"
"19.00000","31.63255","0.73185"
"19.10000","31.79919","0.73514"
"19.20000","31.96578","0.74271"
"19.30000","32.13231","0.74166"
"19.40000","32.29900","0.74396"
"19.50000","32.46596","0.75531"
"19.60000","32.63253","0.78042"
"19.70000","32.79927","0.78008"
"19.80000","32.96590","0.78798"
"19.90000","33.13254","0.80158"
"20.00000","33.29921","0.81340"
"20.10000","33.46579","0.81993"
"20.20000","33.63243","0.82438"
"20.30000","33.79905","0.81919"
"20.40000","33.96569","0.81941"
"20.50000","34.13248","0.83558"
"20.60000","34.29927","0.84314"
"20.70000","34.46603","0.84622"
"20.80000","34.63245","0.85589"
"20.90000","34.79901","0.87876"
"21.00000","34.96578","0.88886"
"21.10000","35.13249","0.89385"
"21.20000","35.29919","0.88867"
"21.30000","35.46569","0.89326"
"21.40000","35.63247","0.88979"
"21.50000","35.79921","0.88922"
"21.60000","35.96597","0.88862"
"21.70000","36.13256","0.89734"
"21.80000","36.29914","0.90347"
"21.90000","36.46584","0.93876"
"22.00000","36.63248","0.95642"
"22.10000","36.79911","0.95388"
"22.20000","36.96572","0.96177"
"22.30000","37.13238","0.97078"
"22.40000","37.29917","0.97407"
"22.50000","37.46594","0.96459"
"22.60000","37.63266","0.98043"
"22.70000","37.79932","0.99214"
"22.80000","37.96569","1.00396"
"22.90000","38.13243","1.02328"
"23.00000","38.29908","1.02627"
"23.10000","38.46574","1.04073"
"23.20000","38.63249","1.03980"
"23.30000","38.79916","1.03443"
"23.40000","38.96592","1.03588"
"23.50000","39.13258","1.02987"
"23.60000","39.29922","1.03762"
"23.70000","39.46583","1.03871"
"23.80000","39.63236","1.05901"
"23.90000","39.79904","1.06724"
"24.00000","39.96565","1.09602"
"24.10000","40.13257","1.10138"
"24.20000","40.29939","1.10664"
"24.30000","40.46596","1.10807"
"24.40000","40.63253","1.11455"
"24.50000","40.79918","1.10481"
"24.60000","40.96584","1.11123"
"24.70000","41.13243","1.12043"
"24.80000","41.29905","1.11815"
"24.90000","41.46577","1.13816"
"25.00000","41.63243","1.15103"
"25.10000","41.79931","1.14930"
"25.20000","41.96605","1.14580"
"25.30000","42.13253","1.15750"
"25.40000","42.29910","1.16343"
"25.50000","42.46571","1.14826"
"25.60000","42.63239","1.13549"
"25.70000","42.79915","1.14742"
"25.80000","42.96589","1.15780"
"25.90000","43.13245","1.18748"
"26.00000","43.29922","1.21410"
"26.10000","43.46591","1.20837"
"26.20000","43.63259","1.20635"
"26.30000","43.79911","1.21647"
"26.40000","43.96576","1.21175"
"26.50000","44.13254","1.21846"
"26.60000","44.29914","1.22122"
"26.70000","44.46577","1.22841"
"26.80000","44.63243","1.22980"
"26.90000","44.79923","1.24918"
"27.00000","44.96591","1.26071"
"27.10000","45.13257","1.26120"
"27.20000","45.29926","1.27626"
"27.30000","45.46577","1.28218"
"27.40000","45.63245","1.27945"
"27.50000","45.79908","1.28912"
"27.60000","45.96572","1.28712"
"27.70000","46.13251","1.28285"
"27.80000","46.29918","1.29560"
"27.90000","46.46595","1.32020"
"28.00000","46.63258","1.32828"
"28.10000","46.79922","1.32853"
"28.20000","46.96584","1.33416"
"28.30000","47.13247","1.34361"
"28.40000","47.29912","1.35260"
"28.50000","47.46568","1.37555"
"28.60000","47.63240","1.39058"
"28.70000","47.79941","1.38803"
"28.80000","47.96605","1.39083"
"28.90000","48.13257","1.40645"
"29.00000","48.29914","1.41108"
"29.10000","48.46575","1.42141"
"29.20000","48.63248","1.40895"
"29.30000","48.79908","1.40242"
"29.40000","48.96571","1.40905"
"29.50000","49.13246","1.40488"
"29.60000","49.29922","1.42176"
"29.70000","49.46601","1.44101"
"29.80000","49.63262","1.44418"
"29.90000","49.79919","1.47468"
"30.00000","49.96582","1.48664"
"30.10000","50.13232","1.49439"
"30.20000","50.29914","1.49129"
"30.30000","50.46582","1.50727"
"30.40000","50.63269","1.51610"
"30.50000","50.79922","1.53582"
"30.60000","50.96593","1.55130"
"30.70000","51.13255","1.55764"
"30.80000","51.29918","1.54376"
"30.90000","51.46580","1.56695"
"31.00000","51.63245","1.59373"
"31.10000","51.79914","1.58226"
"31.20000","51.96577","1.58103"
"31.30000","52.13253","1.58214"
"31.40000","52.29921","1.58540"
"31.50000","52.46599","1.58942"
"31.60000","52.63251","1.61583"
"31.70000","52.79921","1.63099"
"31.80000","52.96604","1.62575"
"31.90000","53.13245","1.63397"
"32.00000","53.29904","1.67014"
"32.10000","53.46572","1.67391"
"32.20000","53.63248","1.66429"
"32.30000","53.79924","1.67335"
"32.40000","53.96596","1.68230"
"32.50000","54.13253","1.71305"
"32.60000","54.29924","1.73578"
"32.70000","54.46582","1.73564"
"32.80000","54.63245","1.72856"
"32.90000","54.79914","1.73927"
"33.00000","54.96571","1.74813"
"33.10000","55.13240","1.74712"
"33.20000","55.29920","1.74338"
"33.30000","55.46624","1.73566"
"33.40000","55.63263","1.74496"
"33.50000","55.79926","1.75847"
"33.60000","55.96576","1.78919"
"33.70000","56.13252","1.79855"
"33.80000","56.29919","1.81138"
"33.90000","56.46569","1.80901"
"34.00000","56.63243","1.83630"
"34.10000","56.79929","1.84341"
"34.20000","56.96594","1.84198"
"34.30000","57.13254","1.84513"
"34.40000","57.29924","1.85344"
"34.50000","57.46580","1.90538"
"34.60000","57.63240","1.94223"
"34.70000","57.79905","1.96305"
"34.80000","57.96587","1.97178"
"34.90000","58.13249","1.96840"
"35.00000","58.29943","1.97759"
"35.10000","58.46593","1.97417"
"35.20000","58.63257","1.97153"
"35.30000","58.79919","1.95116"
"35.40000","58.96581","1.95664"
"35.50000","59.13238","1.98344"
"35.60000","59.29908","2.02771"
"35.70000","59.46592","2.05352"
"35.80000","59.63249","2.06912"
"35.90000","59.79926","2.08404"
"36.00000","59.96600","2.10078"
"36.10000","60.13258","2.11265"
"36.20000","60.29914","2.11740"
"36.30000","60.46580","2.12851"
"36.40000","60.63269","2.15448"
"36.50000","60.79910","2.20827"
"36.60000","60.96576","2.24878"
"36.70000","61.13255","2.31127"
"36.80000","61.29922","2.33467"
"36.90000","61.46597","2.35681"
"37.00000","61.63255","2.35292"
"37.10000","61.79915","2.35292"
"37.20000","61.96581","2.35739"
"37.30000","62.13252","2.36559"
"37.40000","62.29909","2.36535"
"37.50000","62.46573","2.38365"
"37.60000","62.63247","2.41272"
"37.70000","62.79923","2.44418"
"37.80000","62.96594","2.49379"
"37.90000","63.13273","2.52619"
"38.00000","63.29925","2.55594"
"38.10000","63.46583","2.58045"
"38.20000","63.63246","2.59794"
"38.30000","63.79915","2.60786"
"38.40000","63.96566","2.61095"
"38.50000","64.13245","2.63217"
"38.60000","64.29922","2.69859"
"38.70000","64.46597","2.77067"
"38.80000","64.63259","2.84896"
"38.90000","64.79918","2.91847"
"39.00000","64.96584","2.96847"
"39.10000","65.13248","2.99729"
"39.20000","65.29913","3.02833"
"39.30000","65.46561","3.06994"
"39.40000","65.63242","3.10608"
"39.50000","65.79932","3.12314"
"39.60000","65.96600","3.14856"
"39.70000","66.13254","3.17537"
"39.80000","66.29922","3.22479"
"39.90000","66.46580","3.28023"
"40.00000","66.63241","3.35534"
"40.10000","66.79906","3.41935"
"40.20000","66.96575","3.51534"
"40.30000","67.13252","3.58032"
"40.40000","67.29929","3.63081"
"40.50000","67.46601","3.68465"
"40.60000","67.63255","3.74045"
"40.70000","67.79916","3.81342"
"40.80000","67.96579","3.87904"
"40.90000","68.13239","3.90341"
"41.00000","68.29924","3.95816"
"41.10000","68.46582","4.02699"
"41.20000","68.63249","4.11400"
"41.30000","68.79928","4.22267"
"41.40000","68.96597","4.31851"
"41.50000","69.13252","4.41787"
"41.60000","69.29916","4.50559"
"41.70000","69.46573","4.59811"
"41.80000","69.63252","4.66646"
"41.90000","69.79911","4.71873"
"42.00000","69.96571","4.77477"
"42.10000","70.13249","4.85314"
"42.20000","70.29920","4.91653"
"42.30000","70.46595","4.97064"
"42.40000","70.63251","5.01803"
"42.50000","70.79924","5.08340"
"42.60000","70.96587","5.14499"
"42.70000","71.13249","5.21170"
"42.80000","71.29910","5.29489"
"42.90000","71.46576","5.40052"
"43.00000","71.63250","5.49917"
"43.10000","71.79926","5.59158"
"43.20000","71.96597","5.68074"
"43.30000","72.13259","5.75311"
"43.40000","72.29916","5.81772"
"43.50000","72.46574","5.86905"
"43.60000","72.63256","5.95378"
"43.70000","72.79910","6.03631"
"43.80000","72.96574","6.11508"
"43.90000","73.13230","6.19226"
"44.00000","73.29917","6.27574"
"44.10000","73.46605","6.36579"
"44.20000","73.63255","6.46030"
"44.30000","73.79929","6.56905"
"44.40000","73.96576","6.69965"
"44.50000","74.13233","6.81386"
"44.60000","74.29903","6.92939"
"44.70000","74.46570","7.04167"
"44.80000","74.63247","7.15023"
"44.90000","74.79935","7.23251"
"45.00000","74.96602","7.31506"
"45.02100","75.00098","7.33532"