File: characterization/bend_mod_1/mod_1_bend_trial_1.is_tens_RawData/Mod1_Trial1_RawData_1.csv
Strain : Tensile strain (Extension) gauge length,"100.00000",mm
Strain : Time at removal,,s

Time,Extension,Load
(s),(mm),(N)
"0.00000","-7.39097","-0.01684"
"0.10000","-7.26628","-0.01938"
"0.20000","-7.09276","-0.00913"
"0.30000","-6.92533","-0.01092"
"0.40000","-6.75858","-0.01333"
"0.50000","-6.59196","-0.01846"
"0.60000","-6.42538","-0.01131"
"0.70000","-6.25849","-0.00466"
"0.80000","-6.09170","-0.00592"
"0.90000","-5.92502","-0.01090"
"1.00000","-5.75848","-0.00733"
"1.10000","-5.59191","-0.00785"
"1.20000","-5.42533","-0.01149"
"1.30000","-5.25861","-0.01784"
"1.40000","-5.09195","-0.01010"
"1.50000","-4.92527","-0.00768"
"1.60000","-4.75848","-0.01416"
"1.70000","-4.59175","-0.00791"
"1.80000","-4.42508","-0.01662"
"1.90000","-4.25851","-0.01461"
"2.00000","-4.09189","-0.00805"
"2.10000","-3.92539","-0.00698"
"2.20000","-3.75865","-0.01719"
"2.30000","-3.59179","-0.01221"
"2.40000","-3.42515","-0.01395"
"2.50000","-3.25864","-0.00675"
"2.60000","-3.09173","-0.01216"
"2.70000","-2.92507","-0.01049"
"2.80000","-2.75849","-0.01726"
"2.90000","-2.59193","-0.01115"
"3.00000","-2.42527","-0.00918"
"3.10000","-2.25867","-0.01199"
"3.20000","-2.09194","-0.00737"
"3.30000","-1.92527","-0.01320"
"3.40000","-1.75847","-0.00514"
"3.50000","-1.59178","-0.00816"
"3.60000","-1.42507","-0.00248"
"3.70000","-1.25852","-0.00673"
"3.80000","-1.09187","-0.01045"
"3.90000","-0.92517","-0.00694"
"4.00000","-0.75864","-0.00877"
"4.10000","-0.59193","-0.00486"
"4.20000","-0.42525","-0.01088"
"4.30000","-0.25851","0.00240"
"4.40000","-0.09180","-0.00940"
"4.50000","0.07496","-0.01522"
"4.60000","0.24147","-0.00734"
"4.70000","0.40799","-0.00531"
"4.80000","0.57477","-0.01185"
"4.90000","0.74144","-0.00735"
"5.00000","0.90805","-0.00696"
"5.10000","1.07463","0.00458"
"5.20000","1.24132","-0.01228"
"5.30000","1.40825","-0.01346"
"5.40000","1.57517","-0.00230"
"5.50000","1.74152","-0.01036"
"5.60000","1.90806","-0.00505"
"5.70000","2.07468","-0.00293"
"5.80000","2.24134","-0.00350"
"5.90000","2.40805","-0.00278"
"6.00000","2.57478","-0.00557"
"6.10000","2.74142","-0.00449"
"6.20000","2.90825","-0.00004"
"6.30000","3.07497","-0.00696"
"6.40000","3.24159","-0.00202"
"6.50000","3.40804","-0.00271"
"6.60000","3.57463","0.00108"
"6.70000","3.74128","-0.00045"
"6.80000","3.90805","0.00097"
"6.90000","4.07491","-0.00303"
"7.00000","4.24154","-0.00834"
"7.10000","4.40816","-0.00553"
"7.20000","4.57486","-0.00223"
"7.30000","4.74152","-0.00200"
"7.40000","4.90812","-0.00041"
"7.50000","5.07469","-0.00670"
"7.60000","5.24133","-0.00467"
"7.70000","5.40802","-0.00906"
"7.80000","5.57472","-0.00378"
"7.90000","5.74142","-0.00647"
"8.00000","5.90831","-0.00008"
"8.10000","6.07494","-0.00031"
"8.20000","6.24142","0.00202"
"8.30000","6.40805","-0.00654"
"8.40000","6.57477","-0.00278"
"8.50000","6.74149","0.00121"
"8.60000","6.90810","0.00236"
"8.70000","7.07469","0.00450"
"8.80000","7.24149","-0.00200"
"8.90000","7.40830","0.00385"
"9.00000","7.57493","0.00247"
"9.10000","7.74148","0.00014"
"9.20000","7.90810","-0.00224"
"9.30000","8.07467","0.00945"
"9.40000","8.24139","0.00438"
"9.50000","8.40809","0.00820"
"9.60000","8.57482","0.00178"
"9.70000","8.74132","-0.00195"
"9.80000","8.90806","0.00505"
"9.90000","9.07492","0.00404"
"10.00000","9.24158","0.00257"
"10.10000","9.40818","0.00688"
"10.20000","9.57463","0.00628"
"10.30000","9.74138","0.00024"
"10.40000","9.90802","0.00577"
"10.50000","10.07472","0.00205"
"10.60000","10.24145","0.00344"
"10.70000","10.40814","0.00057"
"10.80000","10.57497","0.00068"
"10.90000","10.74152","0.01362"
"11.00000","10.90800","0.00565"
"11.10000","11.07468","0.00427"
"11.20000","11.24129","0.01336"
"11.30000","11.40796","0.00757"
"11.40000","11.57473","0.00913"
"11.50000","11.74174","0.01364"
"11.60000","11.90827","0.00741"
"11.70000","12.07475","0.00611"
"11.80000","12.24149","0.00661"
"11.90000","12.40814","0.00141"
"12.00000","12.57471","0.01160"
"12.10000","12.74134","0.00234"
"12.20000","12.90798","0.01423"
"12.30000","13.07476","0.01070"
"12.40000","13.24146","0.00799"
"12.50000","13.40824","0.01471"
"12.60000","13.57502","0.00659"
"12.70000","13.74141","0.00790"
"12.80000","13.90799","0.01285"
"12.90000","14.07461","0.01735"
"13.00000","14.24149","0.01330"
"13.10000","14.40811","0.01646"
"13.20000","14.57472","0.01199"
"13.30000","14.74144","0.01171"
"13.40000","14.90823","0.01285"
"13.50000","15.07501","0.01406"
"13.60000","15.24147","0.01239"
"13.70000","15.40798","0.01483"
"13.80000","15.57474","0.01849"
"13.90000","15.74131","0.01062"
"14.00000","15.90812","0.01396"
"14.10000","16.07483","0.00983"
"14.20000","16.24140","0.01663"
"14.30000","16.40810","0.01348"
"14.40000","16.57480","0.01188"
"14.50000","16.74152","0.01657"
"14.60000","16.90813","0.01414"
"14.70000","17.07494","0.01406"
"14.80000","17.24134","0.01585"
"14.90000","17.40801","0.01895"
"15.00000","17.57475","0.01314"
"15.10000","17.74150","0.01711"
"15.20000","17.90815","0.01137"
"15.30000","18.07494","0.02199"
"15.40000","18.24154","0.02875"
"15.50000","18.40812","0.02731"
"15.60000","18.57472","0.01814"
"15.70000","18.74131","0.02038"
"15.80000","18.90800","0.02448"
"15.90000","19.07465","0.02700"
"16.00000","19.24145","0.02318"
"16.10000","19.40843","0.03144"
"16.20000","19.57489","0.02770"
"16.30000","19.74144","0.02627"
"16.40000","19.90808","0.03110"
"16.50000","20.07473","0.02730"
"16.60000","20.24143","0.02928"
"16.70000","20.40799","0.03075"
"16.80000","20.57469","0.03517"
"16.90000","20.74144","0.03046"
"17.00000","20.90824","0.02943"
"17.10000","21.07489","0.03482"
"17.20000","21.24155","0.03086"
"17.30000","21.40808","0.03002"
"17.40000","21.57462","0.03836"
"17.50000","21.74131","0.03684"
"17.60000","21.90828","0.04078"
"17.70000","22.07478","0.04089"
"17.80000","22.24149","0.02944"
"17.90000","22.40821","0.03831"
"18.00000","22.57497","0.03667"
"18.10000","22.74158","0.03952"
"18.20000","22.90803","0.03880"
"18.30000","23.07467","0.05208"
"18.40000","23.24138","0.04730"
"18.50000","23.40807","0.05262"
"18.60000","23.57478","0.05463"
"18.70000","23.74150","0.06558"
"18.80000","23.90826","0.06585"
"18.90000","24.07487","0.06114"
"19.00000","24.24144","0.07275"
"19.10000","24.40808","0.08473"
"19.20000","24.57473","0.08094"
"19.30000","24.74146","0.08440"
"19.40000","24.90801","0.09420"
"19.50000","25.07474","0.10486"
"19.60000","25.24147","0.10245"
"19.70000","25.40815","0.11024"
"19.80000","25.57496","0.12105"
"19.90000","25.74152","0.11487"
"20.00000","25.90815","0.12395"
"20.10000","26.07475","0.13147"
"20.20000","26.24146","0.13747"
"20.30000","26.40802","0.15265"
"20.40000","26.57471","0.15067"
"20.50000","26.74139","0.15023"
"20.60000","26.90824","0.15912"
"20.70000","27.07511","0.16974"
"20.80000","27.24157","0.17565"
"20.90000","27.40802","0.17202"
"21.00000","27.57472","0.17978"
"21.10000","27.74139","0.18516"
"21.20000","27.90807","0.20343"
"21.30000","28.07473","0.20438"
"21.40000","28.24146","0.21375"
"21.50000","28.40822","0.20786"
"21.60000","28.57498","0.22558"
"21.70000","28.74149","0.22172"
"21.80000","28.90815","0.23675"
"21.90000","29.07468","0.23769"
"22.00000","29.24137","0.25294"
"22.10000","29.40801","0.25642"
"22.20000","29.57481","0.25629"
"22.30000","29.74150","0.26345"
"22.40000","29.90825","0.27992"
"22.50000","30.07483","0.27921"
"22.60000","30.24156","0.29144"
"22.70000","30.40812","0.29708"
"22.80000","30.57472","0.30367"
"22.90000","30.74137","0.31155"
"23.00000","30.90807","0.31110"
"23.10000","31.07472","0.32455"
"23.20000","31.24153","0.32842"
"23.30000","31.40829","0.33700"
"23.40000","31.57494","0.34127"
"23.50000","31.74155","0.34130"
"23.60000","31.90801","0.35375"
"23.70000","32.07466","0.36990"
"23.80000","32.24147","0.37412"
"23.90000","32.40813","0.38377"
"24.00000","32.57474","0.37926"
"24.10000","32.74150","0.38986"
"24.20000","32.90820","0.39217"
"24.30000","33.07495","0.39822"
"24.40000","33.24147","0.41264"
"24.50000","33.40807","0.40799"
"24.60000","33.57483","0.41442"
"24.70000","33.74143","0.42118"
"24.80000","33.90805","0.43468"
"24.90000","34.07473","0.44336"
"25.00000","34.24149","0.44990"
"25.10000","34.40819","0.45938"
"25.20000","34.57498","0.48417"
"25.30000","34.74168","0.48854"
"25.40000","34.90813","0.48099"
"25.50000","35.07462","0.48452"
"25.60000","35.24141","0.48632"
"25.70000","35.40807","0.49654"
"25.80000","35.57478","0.49825"
"25.90000","35.74145","0.50265"
"26.00000","35.90819","0.50111"
"26.10000","36.07479","0.51872"
"26.20000","36.24166","0.52537"
"26.30000","36.40808","0.54123"
"26.40000","36.57475","0.53774"
"26.50000","36.74138","0.53453"
"26.60000","36.90813","0.54885"
"26.70000","37.07465","0.54700"
"26.80000","37.24156","0.55256"
"26.90000","37.40834","0.56090"
"27.00000","37.57491","0.56950"
"27.10000","37.74155","0.57330"
"27.20000","37.90819","0.58766"
"27.30000","38.07472","0.58137"
"27.40000","38.24135","0.60635"
"27.50000","38.40802","0.60022"
"27.60000","38.57478","0.60555"
"27.70000","38.74149","0.61376"
"27.80000","38.90831","0.61791"
"27.90000","39.07499","0.62685"
"28.00000","39.24152","0.62597"
"28.10000","39.40813","0.63024"
"28.20000","39.57457","0.63238"
"28.30000","39.74135","0.64445"
"28.40000","39.90818","0.66267"
"28.50000","40.07491","0.67330"
"28.60000","40.24150","0.68017"
"28.70000","40.40825","0.69374"
"28.80000","40.57494","0.68958"
"28.90000","40.74145","0.69380"
"29.00000","40.90807","0.69305"
"29.10000","41.07471","0.69110"
"29.20000","41.24144","0.70383"
"29.30000","41.40808","0.71886"
"29.40000","41.57474","0.72061"
"29.50000","41.74145","0.73472"
"29.60000","41.90819","0.73881"
"29.70000","42.07489","0.74819"
"29.80000","42.24152","0.74945"
"29.90000","42.40838","0.75604"
"30.00000","42.57476","0.75442"
"30.10000","42.74130","0.75553"
"30.20000","42.90807","0.75760"
"30.30000","43.07480","0.77430"
"30.40000","43.24147","0.77613"
"30.50000","43.40820","0.78750"
"30.60000","43.57492","0.80387"
"30.70000","43.74151","0.80133"
"30.80000","43.90807","0.80874"
"30.90000","44.07475","0.81912"
"31.00000","44.24144","0.82043"
"31.10000","44.40804","0.83209"
"31.20000","44.57471","0.82817"
"31.30000","44.74137","0.84361"
"31.40000","44.90839","0.84528"
"31.50000","45.07496","0.85476"
"31.60000","45.24157","0.86785"
"31.70000","45.40813","0.87323"
"31.80000","45.57474","0.87318"
"31.90000","45.74139","0.88530"
"32.00000","45.90805","0.89267"
"32.10000","46.07472","0.88511"
"32.20000","46.24146","0.89264"
"32.30000","46.40820","0.90667"
"32.40000","46.57494","0.91705"
"32.50000","46.74157","0.93237"
"32.60000","46.90809","0.94604"
"32.70000","47.07467","0.95349"
"32.80000","47.24124","0.95496"
"32.90000","47.40806","0.94835"
"33.00000","47.57482","0.95754"
"33.10000","47.74167","0.95969"
"33.20000","47.90823","0.96019"
"33.30000","48.07494","0.96729"
"33.40000","48.24143","0.98185"
"33.50000","48.40808","0.99605"
"33.60000","48.57474","1.00243"
"33.70000","48.74139","1.01355"
"33.80000","48.90808","1.02355"
"33.90000","49.07476","1.03267"
"34.00000","49.24147","1.03178"
"34.10000","49.40822","1.03609"
"34.20000","49.57491","1.03582"
"34.30000","49.74144","1.04127"
"34.40000","49.90805","1.05204"
"34.50000","50.07490","1.06697"
"34.60000","50.24146","1.06898"
"34.70000","50.40799","1.09064"
"34.80000","50.57471","1.09594"
"34.90000","50.74146","1.10028"
"35.00000","50.90825","1.08660"
"35.10000","51.07492","1.08518"
"35.20000","51.24149","1.10772"
"35.30000","51.40808","1.10930"
"35.40000","51.57468","1.11544"
"35.50000","51.74141","1.12174"
"35.60000","51.90811","1.12856"
"35.70000","52.07474","1.12743"
"35.80000","52.24136","1.14621"
"35.90000","52.40807","1.16134"
"36.00000","52.57507","1.16971"
"36.10000","52.74163","1.16193"
"36.20000","52.90816","1.16455"
"36.30000","53.07470","1.17755"
"36.40000","53.24141","1.18646"
"36.50000","53.40811","1.19025"
"36.60000","53.57474","1.20552"
"36.70000","53.74150","1.21464"
"36.80000","53.90821","1.22141"
"36.90000","54.07487","1.22648"
"37.00000","54.24155","1.23841"
"37.10000","54.40820","1.23567"
"37.20000","54.57473","1.24246"
"37.30000","54.74125","1.24467"
"37.40000","54.90792","1.25036"
"37.50000","55.07472","1.24676"
"37.60000","55.24148","1.27174"
"37.70000","55.40847","1.28196"
"37.80000","55.57486","1.28833"
"37.90000","55.74147","1.29562"
"38.00000","55.90811","1.31088"
"38.10000","56.07476","1.32251"
"38.20000","56.24140","1.31604"
"38.30000","56.40803","1.32149"
"38.40000","56.57481","1.31929"
"38.50000","56.74148","1.33077"
"38.60000","56.90828","1.34431"
"38.70000","57.07492","1.34604"
"38.80000","57.24142","1.35598"
"38.90000","57.40799","1.37344"
"39.00000","57.57469","1.37332"
"39.10000","57.74147","1.38054"
"39.20000","57.90813","1.37329"
"39.30000","58.07465","1.37656"
"39.40000","58.24147","1.38834"
"39.50000","58.40820","1.39583"
"39.60000","58.57499","1.41685"
"39.70000","58.74154","1.40663"
"39.80000","58.90805","1.41884"
"39.90000","59.07470","1.41381"
"40.00000","59.24140","1.42312"
"40.10000","59.40807","1.42956"
"40.20000","59.57475","1.43002"
"40.30000","59.74139","1.43893"
"40.40000","59.90807","1.44375"
"40.50000","60.07482","1.47131"
"40.60000","60.24158","1.49036"
"40.70000","60.40820","1.50705"
"40.80000","60.57471","1.50788"
"40.90000","60.74138","1.50590"
"41.00000","60.90811","1.50984"
"41.10000","61.07482","1.51608"
"41.20000","61.24149","1.51580"
"41.30000","61.40816","1.51850"
"41.40000","61.57491","1.52351"
"41.50000","61.74147","1.53575"
"41.60000","61.90815","1.54342"
"41.70000","62.07476","1.54865"
"41.80000","62.24137","1.54602"
"41.90000","62.40807","1.55021"
"42.00000","62.57460","1.54775"
"42.10000","62.74143","1.56340"
"42.20000","62.90833","1.56072"
"42.30000","63.07495","1.54858"
"42.40000","63.24150","1.56880"
"42.50000","63.40812","1.57883"
"42.60000","63.57471","1.60703"
"42.70000","63.74139","1.60186"
"42.80000","63.90805","1.61837"
"42.90000","64.07473","1.63025"
"43.00000","64.24150","1.64684"
"43.10000","64.40826","1.65718"
"43.20000","64.57499","1.65425"
"43.30000","64.74149","1.65227"
"43.40000","64.90804","1.66669"
"43.50000","65.07462","1.67420"
"43.60000","65.24137","1.66981"
"43.70000","65.40820","1.66572"
"43.80000","65.57476","1.67940"
"43.90000","65.74136","1.67403"
"44.00000","65.90825","1.68484"
"44.10000","66.07495","1.69918"
"44.20000","66.24155","1.70151"
"44.30000","66.40805","1.70738"
"44.40000","66.57468","1.70512"
"44.50000","66.74139","1.72513"
"44.60000","66.90806","1.74502"
"44.70000","67.07481","1.75209"
"44.80000","67.24146","1.75828"
"44.90000","67.40819","1.77202"
"45.00000","67.57484","1.78754"
"45.10000","67.74149","1.78840"
"45.20000","67.90818","1.78839"
"45.30000","68.07481","1.79553"
"45.40000","68.24140","1.80147"
"45.50000","68.40806","1.83550"
"45.60000","68.57478","1.82916"
"45.70000","68.74157","1.82297"
"45.80000","68.90820","1.82175"
"45.90000","69.07493","1.83621"
"46.00000","69.24155","1.84798"
"46.10000","69.40810","1.85057"
"46.20000","69.57478","1.86184"
"46.30000","69.74142","1.86031"
"46.40000","69.90808","1.87646"
"46.50000","70.07467","1.89648"
"46.60000","70.24135","1.91297"
"46.70000","70.40823","1.93044"
"46.80000","70.57496","1.96087"
"46.90000","70.74166","1.95718"
"47.00000","70.90809","1.96528"
"47.10000","71.07470","1.97562"
"47.20000","71.24140","1.98858"
"47.30000","71.40803","1.98682"
"47.40000","71.57472","1.98708"
"47.50000","71.74149","2.00264"
"47.60000","71.90832","2.00239"
"47.70000","72.07494","2.02425"
"47.80000","72.24150","2.01679"
"47.90000","72.40811","2.06186"
"48.00000","72.57468","2.06591"
"48.10000","72.74131","2.06144"
"48.20000","72.90813","2.05610"
"48.30000","73.07488","2.05168"
"48.40000","73.24155","2.06348"
"48.50000","73.40819","2.09467"
"48.60000","73.57496","2.10642"
"48.70000","73.74152","2.12546"
"48.80000","73.90818","2.15209"
"48.90000","74.07471","2.19802"
"49.00000","74.24139","2.21685"
"49.10000","74.40803","2.23081"
"49.20000","74.57481","2.22928"
"49.30000","74.74145","2.25308"
"49.40000","74.90828","2.26108"
"49.50000","75.07498","2.28435"
"49.60000","75.24146","2.33305"
"49.70000","75.40801","2.33901"
"49.80000","75.57481","2.36160"
"49.90000","75.74143","2.39221"
"50.00000","75.90807","2.43189"
"50.10000","76.07475","2.44339"
"50.20000","76.24151","2.46029"
"50.30000","76.40830","2.49185"
"50.40000","76.57488","2.50900"
"50.50000","76.74153","2.52610"
"50.60000","76.90809","2.57181"
"50.70000","77.07469","2.62637"
"50.80000","77.24142","2.65587"
"50.90000","77.40817","2.72943"
"51.00000","77.57475","2.77050"
"51.10000","77.74140","2.80030"
"51.20000","77.90814","2.81609"
"51.30000","78.07496","2.84549"
"51.40000","78.24158","2.88965"
"51.50000","78.40835","2.92471"
"51.60000","78.57465","2.96452"
"51.70000","78.74139","3.01371"
"51.80000","78.90809","3.06208"
"51.90000","79.07475","3.11213"
"52.00000","79.24146","3.16022"
"52.10000","79.40820","3.21014"
"52.20000","79.57500","3.28238"
"52.30000","79.74152","3.35522"
"52.40000","79.90808","3.43120"
"52.50000","80.07472","3.48972"
"52.60000","80.24133","3.55069"
"52.70000","80.40798","3.58845"
"52.80000","80.57474","3.64541"
"52.90000","80.74171","3.70703"
"53.00000","80.90838","3.77300"
"53.10000","81.07489","3.83340"
"53.20000","81.24154","3.92828"
"53.30000","81.40815","3.97786"
"53.40000","81.57476","3.98936"
"53.50000","81.74136","4.05601"
"53.60000","81.90804","4.14454"
"53.70000","82.07474","4.24431"
"53.80000","82.24142","4.33761"
"53.90000","82.40824","4.41683"
"54.00000","82.57496","4.46760"
"54.10000","82.74151","4.55229"
"54.20000","82.90810","4.63809"
"54.30000","83.07471","4.70078"
"54.40000","83.24153","4.76512"
"54.50000","83.40815","4.81461"
"54.60000","83.57483","4.87993"
"54.70000","83.74152","4.97150"
"54.80000","83.90828","5.00643"
"54.90000","84.07496","5.07572"
"55.00000","84.24154","5.14944"
"55.10000","84.40806","5.20470"
"55.20000","84.57475","5.27533"
"55.30000","84.74129","5.35800"
"55.40000","84.90815","5.45055"
"55.50000","85.07484","5.55032"
"55.60000","85.24149","5.64262"
"55.70000","85.40815","5.72777"
"55.80000","85.57484","5.80097"
"55.90000","85.74155","5.89384"
"56.00000","85.90822","5.98300"
"56.10000","86.07476","6.05913"
"56.20000","86.24139","6.14712"
"56.30000","86.40813","6.24749"
"56.40000","86.57471","6.33980"
"56.50000","86.74146","6.42302"
"56.60000","86.90822","6.50797"
"56.70000","87.07490","6.59100"
"56.80000","87.24155","6.67669"
"56.90000","87.40814","6.77447"
"57.00000","87.57475","6.86128"
"57.10000","87.74139","6.94227"
"57.20000","87.90807","7.01355"
"57.25600","88.00147","7.03987"